<?xml version="1.0" ?>
<robot name="plate">

  <material name="industrial-blue">
    <color rgba="0.11372549019607843 0.34509803921568627 0.6549019607843137 1" />
  </material>

  <material name="arches-blue">
    <color rgba="0.0 0.6235294117647059 0.8313725490196079 1" />
  </material>

  <material name = "heritage-orange">
    <color rgba = "0.96078431 0.50980392 0.11764706 1" />
  </material>

  <link name="world"/>

  <link name="outer" concave="yes">
     <visual>
       <origin rpy="0 0 0" xyz="0 0 0"/>
       <geometry>
         <mesh filename="outer.stl" scale="1 1 1"/>
       </geometry>
       <material name = "industrial-blue"/>
     </visual>
     <collision concave="yes">
       <origin rpy="0 0 0" xyz="0 0 0"/>
       <geometry>
         <mesh filename="outer.stl" scale="1 1 1"/>
       </geometry>
     </collision>
     <inertial>
       <origin rpy="0 0 0" xyz="0 0 0"/>
       <mass value="1"/>
       <inertia ixx="0.01" ixy="0" ixz="0" iyy="0.01" iyz="0" izz="0.01"/>
     </inertial>
   </link>

  <link name="inner" concave="yes">
    <visual>
      <origin rpy="0 0 0" xyz="0 0 0"/>
      <geometry>
        <mesh filename="inner.stl" scale="1 1 1"/>
      </geometry>
      <material name = "arches-blue"/>
    </visual>
    <collision concave="yes">
      <origin rpy="0 0 0" xyz="0 0 0"/>
      <geometry>
        <mesh filename="inner.stl" scale="1 1 1"/>
      </geometry>
    </collision>
    <inertial>
      <origin rpy="0 0 0" xyz="0 0 0"/>
      <mass value="1"/>
      <inertia ixx="0.01" ixy="0" ixz="0" iyy="0.01" iyz="0" izz="0.01"/>
    </inertial>
  </link>

  <joint name="world_to_outer" type="continuous">
		<parent link = "world" />
		<child link = "outer" />
		<origin xyz = "0 0 0" />
		<axis xyz = "0 1 0" />
		<limit effort="1000" velocity="1000"/>
	</joint>

  <joint name="outer_to_inner" type="continuous">
		<parent link = "outer" />
		<child link = "inner" />
		<origin xyz = "0 0 0" />
		<axis xyz = "1 0 0" />
		<limit effort="1000" velocity="1000"/>
	</joint>

</robot>
